Workbook
Name Slicer_Date_Hierarchy: #N/A
Name Slicer_Product: #N/A
Name Slicer_Region: #N/A

Sheet sales_data
A1: Date | B1: Year | C1: Month | D1: OrderID | E1: Customer | F1: Region | G1: Salesperson | H1: Product | I1: Quantity | J1: Unit Price | K1: Discount % | L1: Unit Cost | M1: Sales | N1: Profit | O1: frequent vs once
A2: 45892 | B2: =TEXT(A2,"yyyy") -> 2025 | C2: =TEXT(A2,"mmm") -> Aug | D2: 1352 | E2: Bob Lee | F2: South | G2: Alice | H2: Monitor | I2: 4 | J2: 276 | K2: 0.25 | L2: 193.2 | M2: =I2*J2*(1-K2) -> 828 | N2: =M2-L2*I2 -> 55.2 | O2: =IF(COUNTIF(E2:E501,E2)>1,"F","O") -> F
A3: 45891 | B3: =TEXT(A3,"yyyy") -> 2025 | C3: =TEXT(A3,"mmm") -> Aug | D3: 1208 | E3: Tom Brown | F3: East | G3: Diana | H3: Keyboard | I3: 8 | J3: 280 | K3: 0.15 | L3: 196 | M3: =I3*J3*(1-K3) -> 1904 | N3: =M3-L3*I3 -> 336 | O3: =IF(COUNTIF(E3:E502,E3)>1,"F","O") -> F
A4: 45889 | B4: =TEXT(A4,"yyyy") -> 2025 | C4: =TEXT(A4,"mmm") -> Aug | D4: 1337 | E4: Carlos Diaz | F4: North | G4: Ethan | H4: Headphones | I4: 5 | J4: 180 | K4: 0 | L4: 126 | M4: =I4*J4*(1-K4) -> 900 | N4: =M4-L4*I4 -> 270 | O4: =IF(COUNTIF(E4:E503,E4)>1,"F","O") -> F
A5: 45884 | B5: =TEXT(A5,"yyyy") -> 2025 | C5: =TEXT(A5,"mmm") -> Aug | D5: 1338 | E5: Sara Khan | F5: South | G5: Fiona | H5: Laptop | I5: 10 | J5: 453 | K5: 0 | L5: 317.1 | M5: =I5*J5*(1-K5) -> 4530 | N5: =M5-L5*I5 -> 1359 | O5: =IF(COUNTIF(E5:E504,E5)>1,"F","O") -> F
A6: 45882 | B6: =TEXT(A6,"yyyy") -> 2025 | C6: =TEXT(A6,"mmm") -> Aug | D6: 1035 | E6: Priya Patel | F6: South | G6: Diana | H6: Printer | I6: 4 | J6: 98 | K6: 0.3 | L6: 68.6 | M6: =I6*J6*(1-K6) -> 274.4 | N6: =M6-L6*I6 -> 0 | O6: =IF(COUNTIF(E6:E505,E6)>1,"F","O") -> F
A7: 45882 | B7: =TEXT(A7,"yyyy") -> 2025 | C7: =TEXT(A7,"mmm") -> Aug | D7: 1128 | E7: John Doe | F7: South | G7: Bob | H7: Keyboard | I7: 2 | J7: 468 | K7: 0 | L7: 327.6 | M7: =I7*J7*(1-K7) -> 936 | N7: =M7-L7*I7 -> 280.8 | O7: =IF(COUNTIF(E7:E506,E7)>1,"F","O") -> F
A8: 45882 | B8: =TEXT(A8,"yyyy") -> 2025 | C8: =TEXT(A8,"mmm") -> Aug | D8: 1314 | E8: Carlos Diaz | F8: South | G8: Ethan | H8: Printer | I8: 10 | J8: 464 | K8: 0 | L8: 324.8 | M8: =I8*J8*(1-K8) -> 4640 | N8: =M8-L8*I8 -> 1392 | O8: =IF(COUNTIF(E8:E507,E8)>1,"F","O") -> F
A9: 45882 | B9: =TEXT(A9,"yyyy") -> 2025 | C9: =TEXT(A9,"mmm") -> Aug | D9: 1071 | E9: Bob Lee | F9: East | G9: Alice | H9: Printer | I9: 1 | J9: 480 | K9: 0 | L9: 336 | M9: =I9*J9*(1-K9) -> 480 | N9: =M9-L9*I9 -> 144 | O9: =IF(COUNTIF(E9:E508,E9)>1,"F","O") -> F
A10: 45880 | B10: =TEXT(A10,"yyyy") -> 2025 | C10: =TEXT(A10,"mmm") -> Aug | D10: 1275 | E10: Bob Lee | F10: South | G10: Charlie | H10: Printer | I10: 1 | J10: 304 | K10: 0.15 | L10: 212.8 | M10: =I10*J10*(1-K10) -> 258.4 | N10: =M10-L10*I10 -> 45.6 | O10: =IF(COUNTIF(E10:E509,E10)>1,"F","O") -> F
A11: 45879 | B11: =TEXT(A11,"yyyy") -> 2025 | C11: =TEXT(A11,"mmm") -> Aug | D11: 1356 | E11: Bob Lee | F11: North | G11: Bob | H11: Printer | I11: 3 | J11: 398 | K11: 0.05 | L11: 278.6 | M11: =I11*J11*(1-K11) -> 1134.3 | N11: =M11-L11*I11 -> 298.5 | O11: =IF(COUNTIF(E11:E510,E11)>1,"F","O") -> F
A12: 45879 | B12: =TEXT(A12,"yyyy") -> 2025 | C12: =TEXT(A12,"mmm") -> Aug | D12: 1296 | E12: Alice Smith | F12: East | G12: Diana | H12: Mouse | I12: 5 | J12: 452 | K12: 0.25 | L12: 316.4 | M12: =I12*J12*(1-K12) -> 1695 | N12: =M12-L12*I12 -> 113 | O12: =IF(COUNTIF(E12:E511,E12)>1,"F","O") -> F
A13: 45878 | B13: =TEXT(A13,"yyyy") -> 2025 | C13: =TEXT(A13,"mmm") -> Aug | D13: 1340 | E13: Jane Roe | F13: South | G13: Alice | H13: Headphones | I13: 6 | J13: 103 | K13: 0.3 | L13: 72.1 | M13: =I13*J13*(1-K13) -> 432.6 | N13: =M13-L13*I13 -> 0 | O13: =IF(COUNTIF(E13:E512,E13)>1,"F","O") -> F
... A501: 45293 | B501: =TEXT(A501,"yyyy") -> 2024 | C501: =TEXT(A501,"mmm") -> Jan | D501: 1499 | E501: Bob Lee | F501: West | G501: Alice | H501: Tablet | I501: 10 | J501: 354 | K501: 0 | L501: 247.8 | M501: =I501*J501*(1-K501) -> 3540 | N501: =M501-L501*I501 -> 1062 | O501: =IF(COUNTIF(E501:E1000,E501)>1,"F","O") -> O

Sheet Pivot_tables
A2: Product sales
A3: Products | B3: Total Sales
A4: Printer | B4: 107372.7
A5: Headphones | B5: 86111.9
A6: Monitor | B6: 85368.8
A7: Mouse | B7: 84432.4
A8: Laptop | B8: 81897.75
A9: Keyboard | B9: 72523.7
A10: Tablet | B10: 72132.7
A11: Smartphone | B11: 69768.45
A12: Grand Total | B12: 280908.2
A14: Region wise sale
A15: Region | B15: Total Sales | C15: Total Profit
A16: East | B16: 174466.35 | C16: 32360.05
A17: West | B17: 169896.4 | C17: 29349.7
A18: South | B18: 150629.85 | C18: 29353.45
A19: North | B19: 88921.8 | C19: 30588.2
A20: Grand Total | B20: 280908.2 | C20: 121651.4
A23: Top 5 customers
A24: Customers | B24: Total Sales
A25: Sara Khan | B25: 85114.3
A26: Carlos Diaz | B26: 82396.9
A27: Jane Roe | B27: 82253.5
A28: Priya Patel | B28: 74383.5
A29: Alice Smith | B29: 70207.8
A30: Grand Total | B30: 394356
A32: Salesperson performance
A33: Salesperson | B33: Total Sales | C33: Sum of Profit
A34: Bob | B34: 129909.1 | C34: 23939.6
A35: Diana | B35: 118774.85 | C35: 20128.05
A36: Ethan | B36: 114961 | C36: 22545.6
A37: Fiona | B37: 107128.15 | C37: 19989.35
A38: Charlie | B38: 95609.7 | C38: 18939.4
A39: Alice | B39: 93225.6 | C39: 16109.4
A40: Grand Total | B40: 280908.2 | C40: 121651.4
A42: Monthly sales trends
A43: Months | B43: Total Sales
A44: Jan | B44: 63807.45
A45: Feb | B45: 57472.1
A46: Mar | B46: 60267.95
...

Sheet kpi_calculation
A1: Row Labels | B1: Sum of Sales | C1: mom% | D1: Sum of Profit | E1: profit% | F1: Average of Sales | G1: Average of Discount % | H1: Count of Order | I1: count% | K1: sum of profit | L1: mom profit%
A2: 2025 | B2: 280908.2 | C2: -0.099591158 | D2: 51701.6 | E2: -0.1097259 | F2: 1337.6581 | G2: 0.14547619 | H2: 210 | I2: -0.27586207 | K2: =INDEX(D2:D3,MATCH(D2,D2:D3)) -> 51701.6 | L2: =INDEX(E2:E3,MATCH(E2,E2:E3,0)) -> -0.1097259
A3: 2024 | B3: 378700.2 | C3: 0.089377525 | D3: 69949.8 | E3: 0.10022712 | F3: 1305.8628 | G3: 0.15 | H3: 290
A4: Grand Total | B4: 280908.2 | C4: 0 | D4: 121651.4 | E4: 0 | F4: 1319.2168 | G4: 0.1481 | H4: 500 | I4: 0.72413793
A7: Row Labels | B7: Sum of Sales | C7: Region wise% | D7: sum of sales | E7: %
A8: East | B8: 174466.35 | C8: 0.26449989 | D8: =INDEX(B8:B11,MATCH(A8,A8:A11)) -> 174466.35 | E8: =INDEX(C8:C11,MATCH(A8,A8:A11)) -> 0.26449989
A9: North | B9: 88921.8 | C9: 0.24956595
A10: South | B10: 150629.85 | C10: 0.22836254
A11: West | B11: 169896.4 | C11: 0.25757161
A12: Grand Total | B12: 280908.2 | C12: 1
A15: Row Labels | B15: Average of Sales | D15: avg %
A16: 2025 | B16: 1337.6581 | D16: =IFERROR((GETPIVOTDATA("[Measures].[Average of Sales]",$A$15,"[sales_data].[Year]","[sales_data].[Year].&[2025]")/GETPIVOTDATA("[Measures].[Average of Sales]",$A$15,"[sales_data].[Year]","[sales_data].[Year].&[2024]"))-1,0) -> 0.024348146
A17: 2024 | B17: 1305.8628
A18: Grand Total | B18: 1319.2168
A21: Row Labels | B21: Sum of Sales | C21: YOY% | D21: YOY%
A22: 2025 | B22: 280908.2 | C22: -0.25823065 | D22: =INDEX(C22:C23,MATCH(A22,A22:A23)) -> -0.25823065
A23: 2024 | B23: 378700.2 | C23: 0
A24: Grand Total | B24: 280908.2 | C24: -0.25823065
A27: Row Labels | B27: Sum of Profit | C27: profit%year
A28: 2025 | B28: 51701.6 | C28: -0.26087566
A29: 2024 | B29: 69949.8 | C29: 0
A30: Grand Total | B30: 121651.4 | C30: 0.73912434

Sheet dashboard_view
A1: SALES PERFORMANCE DASHBOARD 2024-25
A4: TOTAL VALUE | D4: TOTAL ORDERS | G4: PROFIT(month-wise) | J4: EAST | M4: MOM Sales % | P4: TOTAL PROFIT | S4: DISCOUNT % | V4: AVERAGE VALUE
A5: =GETPIVOTDATA("[Measures].[Sum of Sales 2]",kpi_calculation!$A$1) -> 280908.2 | D5: =GETPIVOTDATA("[Measures].[Count of OrderID]",kpi_calculation!$A$1) -> 500 | G5: =kpi_calculation!K2 -> 51701.6 | J5: =kpi_calculation!D8 -> 174466.35 | M5: =GETPIVOTDATA("[Measures].[mom%]",kpi_calculation!$A$1) -> 0 | P5: =GETPIVOTDATA("[Measures].[Sum of Profit]",kpi_calculation!$A$27) -> 121651.4 | S5: =GETPIVOTDATA("[Measures].[Average of Discount %]",kpi_calculation!$A$1) -> 0.1481 | V5: =GETPIVOTDATA("[Measures].[Average of Sales]",kpi_calculation!$A$1) -> 1319.2168
A6: =kpi_calculation!D22 -> -0.25823065 | D6: =IFERROR((GETPIVOTDATA("[Measures].[count%]",kpi_calculation!$A$1,"[Calendar].[Date Hierarchy]","[Calendar].[Date Hierarchy].[Year].&[2025]")),0) -> -0.27586207 | G6: =kpi_calculation!L2 -> -0.1097259 | J6: =kpi_calculation!E8 -> 0.26449989 | P6: =IFERROR((GETPIVOTDATA("[Measures].[profit%year]",kpi_calculation!$A$27,"[Calendar].[Date Hierarchy]","[Calendar].[Date Hierarchy].[Year].&[2025]")),0) -> -0.26087566 | V6: =kpi_calculation!D16 -> 0.024348146

Sheet summary
